/**
  * Scenario: a class defining a method with try/catch and returning 
  * different values
  */
object cuenta {
  method sacar(monto) {
    try {
      if (monto > 0) throw new Exception(message = "saldo insuficiente")
      return 19
    } 
    catch e {
      return 20
    }
  }

}

/**
  * Tests
  */
describe "catching errors" {

  test "method returning a value from a normal flow" {
    assert.equals(19, cuenta.sacar(0))
  }

  test "method returning a value from a catch" {
    assert.equals(20, cuenta.sacar(10))
  }

}