/**
  * Scenario: a wko throwing a user exception in a method
  */
class UserException inherits Exception {
   var valorInvalido = 0
}

object monedero {
  var plata = 500

  method poner(cantidad) {
    if (cantidad < 0) {
      throw new UserException(message="La cantidad debe ser positiva", valorInvalido=cantidad)
    } 
    plata += cantidad
  }

  method sacar(cantidad) { plata -= cantidad }
}

/**
  * Tests
  */
test "exception with message" {
  try {
    monedero.poner(-2)
    assert.fail("No should get here")
  } catch e {
    assert.equals("La cantidad debe ser positiva", e.message())
  }
}
